Workbook

Sheet DSN GROUP (21 Century)
A1: Importantly! - The minimum order amount is € / $ 5,000 per brand - delivery EX Work from the Poland / US warehouse! - this offer is valid within the current month - order is possible only rounded by boxes - due to the raw material crisis in the market, prices could be changed without prior notice | L1: 46135 | N1: Unіt Freight Cost | O1: unit, key | P1: Weight, kg | Q1: Logistic Price | S1: =IFERROR(IF(SUM(S3:S282)=0, "-", L2+Q2), "-") -> -
A2: Item Number | B2: Description | C2: UPC | D2: Item Size | E2: Form | F2: Weight, kg | G2: Case | H2: Wholesale price | I2: RATING | J2: Order | K2: Total | L2: =SUM(K3:K245) -> 0 | P2: =IF(SUM(P3:P282)=0, "-", SUM(P3:P282)) -> - | Q2: =IF(SUM(Q3:Q282)=0, "-", SUM(Q3:Q282)) -> - | S2: Landed Cost
A3: 22668 | B3: B Complex w/C | C3: 740985226681 | D3: 100 | E3: tb | F3: 0.16285132 | G3: 24 | H3: 5.745 | I3: =IFERROR(VLOOKUP("21ST-"&A3,[1]Лист1!$B$16:$P$170,15,FALSE),"С") -> А | K3: =SUM(H3*J3) -> 0 | N3: =IFERROR(IF($N$2*F3=0, "-", $N$2*F3), "-") -> - | O3: =IFERROR(IF(N3>0,H3+N3,"-"),"-") -> - | P3: =IF(J3>0,J3*F3, "-") -> - | Q3: =IFERROR(IF($N$2>0, $N$2*P3, "-"), "-") -> - | S3: =IFERROR(IF(Q3+K3=0, "-", IF(Q3>0, Q3+K3, "-")), "-") -> -
A4: 22251 | B4: B-50 Complex PR | C4: 740985222515 | D4: 60 | E4: tb | F4: 0.093390485 | G4: 24 | H4: 4.965 | I4: =IFERROR(VLOOKUP("21ST-"&A4,[1]Лист1!$B$16:$P$170,15,FALSE),"С") -> А | K4: =SUM(H4*J4) -> 0 | N4: =IFERROR(IF($N$2*F4=0, "-", $N$2*F4), "-") -> - | O4: =IFERROR(IF(N4>0,H4+N4,"-"),"-") -> - | P4: =IF(J4>0,J4*F4, "-") -> - | Q4: =IFERROR(IF($N$2>0, $N$2*P4, "-"), "-") -> - | S4: =IFERROR(IF(Q4+K4=0, "-", IF(Q4>0, Q4+K4, "-")), "-") -> -
A5: 22881 | B5: Biotin 800 mcg | C5: 740985228814 | D5: 110 | E5: tb | F5: 0.080848946 | G5: 24 | H5: 2.475 | I5: =IFERROR(VLOOKUP("21ST-"&A5,[1]Лист1!$B$16:$P$170,15,FALSE),"С") -> А | K5: =SUM(H5*J5) -> 0 | N5: =IFERROR(IF($N$2*F5=0, "-", $N$2*F5), "-") -> - | O5: =IFERROR(IF(N5>0,H5+N5,"-"),"-") -> - | P5: =IF(J5>0,J5*F5, "-") -> - | Q5: =IFERROR(IF($N$2>0, $N$2*P5, "-"), "-") -> - | S5: =IFERROR(IF(Q5+K5=0, "-", IF(Q5>0, Q5+K5, "-")), "-") -> -
A6: 27116 | B6: Biotin 5000 mcg | C6: 740985271162 | D6: 110 | E6: cp | F6: 0.14514561 | G6: 24 | H6: 5.745 | I6: =IFERROR(VLOOKUP("21ST-"&A6,[1]Лист1!$B$16:$P$170,15,FALSE),"С") -> А | K6: =SUM(H6*J6) -> 0 | N6: =IFERROR(IF($N$2*F6=0, "-", $N$2*F6), "-") -> - | O6: =IFERROR(IF(N6>0,H6+N6,"-"),"-") -> - | P6: =IF(J6>0,J6*F6, "-") -> - | Q6: =IFERROR(IF($N$2>0, $N$2*P6, "-"), "-") -> - | S6: =IFERROR(IF(Q6+K6=0, "-", IF(Q6>0, Q6+K6, "-")), "-") -> -
A7: 27757 | B7: Biotin 10,000 mcg | C7: 740985277577 | D7: 120 | E7: tb | F7: 0.083856646 | G7: 24 | H7: 7.425 | I7: =IFERROR(VLOOKUP("21ST-"&A7,[1]Лист1!$B$16:$P$170,15,FALSE),"С") -> А | K7: =SUM(H7*J7) -> 0 | N7: =IFERROR(IF($N$2*F7=0, "-", $N$2*F7), "-") -> - | O7: =IFERROR(IF(N7>0,H7+N7,"-"),"-") -> - | P7: =IF(J7>0,J7*F7, "-") -> - | Q7: =IFERROR(IF($N$2>0, $N$2*P7, "-"), "-") -> - | S7: =IFERROR(IF(Q7+K7=0, "-", IF(Q7>0, Q7+K7, "-")), "-") -> -
A8: 22316 | B8: C 500 mg | C8: 740985223161 | D8: 110 | E8: tb | F8: 0.1339093 | G8: 24 | H8: 3.705 | I8: =IFERROR(VLOOKUP("21ST-"&A8,[1]Лист1!$B$16:$P$170,15,FALSE),"С") -> А | K8: =SUM(H8*J8) -> 0 | N8: =IFERROR(IF($N$2*F8=0, "-", $N$2*F8), "-") -> - | O8: =IFERROR(IF(N8>0,H8+N8,"-"),"-") -> - | P8: =IF(J8>0,J8*F8, "-") -> - | Q8: =IFERROR(IF($N$2>0, $N$2*P8, "-"), "-") -> - | S8: =IFERROR(IF(Q8+K8=0, "-", IF(Q8>0, Q8+K8, "-")), "-") -> -
A9: 22263 | B9: Cal Mag Zinc +D | C9: 740985222638 | D9: 90 | E9: tb | F9: 0.17561985 | G9: 24 | H9: 3.765 | I9: =IFERROR(VLOOKUP("21ST-"&A9,[1]Лист1!$B$16:$P$170,15,FALSE),"С") -> А | K9: =SUM(H9*J9) -> 0 | N9: =IFERROR(IF($N$2*F9=0, "-", $N$2*F9), "-") -> - | O9: =IFERROR(IF(N9>0,H9+N9,"-"),"-") -> - | P9: =IF(J9>0,J9*F9, "-") -> - | Q9: =IFERROR(IF($N$2>0, $N$2*P9, "-"), "-") -> - | S9: =IFERROR(IF(Q9+K9=0, "-", IF(Q9>0, Q9+K9, "-")), "-") -> -
A10: 28048 | B10: Cal Mag Zinc +D | C10: 740985280485 | D10: 250 | E10: tb | F10: 0.44265 | G10: 12 | H10: 9.075 | I10: =IFERROR(VLOOKUP("21ST-"&A10,[1]Лист1!$B$16:$P$170,15,FALSE),"С") -> А | K10: =SUM(H10*J10) -> 0 | N10: =IFERROR(IF($N$2*F10=0, "-", $N$2*F10), "-") -> - | O10: =IFERROR(IF(N10>0,H10+N10,"-"),"-") -> - | P10: =IF(J10>0,J10*F10, "-") -> - | Q10: =IFERROR(IF($N$2>0, $N$2*P10, "-"), "-") -> - | S10: =IFERROR(IF(Q10+K10=0, "-", IF(Q10>0, Q10+K10, "-")), "-") -> -
A11: 22670 | B11: Iron 65 mg (Ferrous Sulfate 325 mg) | C11: 740985226704 | D11: 120 | E11: tb | F11: 0.13909238 | G11: 24 | H11: 4.14 | I11: =IFERROR(VLOOKUP("21ST-"&A11,[1]Лист1!$B$16:$P$170,15,FALSE),"С") -> А | K11: =SUM(H11*J11) -> 0 | N11: =IFERROR(IF($N$2*F11=0, "-", $N$2*F11), "-") -> - | O11: =IFERROR(IF(N11>0,H11+N11,"-"),"-") -> - | P11: =IF(J11>0,J11*F11, "-") -> - | Q11: =IFERROR(IF($N$2>0, $N$2*P11, "-"), "-") -> - | S11: =IFERROR(IF(Q11+K11=0, "-", IF(Q11>0, Q11+K11, "-")), "-") -> -
A12: 22713 | B12: Magnesium 250 mg | C12: 740985227138 | D12: 110 | E12: tb | F12: 0.14755 | G12: 24 | H12: 2.475 | I12: =IFERROR(VLOOKUP("21ST-"&A12,[1]Лист1!$B$16:$P$170,15,FALSE),"С") -> А | K12: =SUM(H12*J12) -> 0 | N12: =IFERROR(IF($N$2*F12=0, "-", $N$2*F12), "-") -> - | O12: =IFERROR(IF(N12>0,H12+N12,"-"),"-") -> - | P12: =IF(J12>0,J12*F12, "-") -> - | Q12: =IFERROR(IF($N$2>0, $N$2*P12, "-"), "-") -> - | S12: =IFERROR(IF(Q12+K12=0, "-", IF(Q12>0, Q12+K12, "-")), "-") -> -
A13: 22658 | B13: Mega Multi for Men | C13: 740985226582 | D13: 90 | E13: tb | F13: 0.22087107 | G13: 12 | H13: 10.17 | I13: =IFERROR(VLOOKUP("21ST-"&A13,[1]Лист1!$B$16:$P$170,15,FALSE),"С") -> А | K13: =SUM(H13*J13) -> 0 | N13: =IFERROR(IF($N$2*F13=0, "-", $N$2*F13), "-") -> - | O13: =IFERROR(IF(N13>0,H13+N13,"-"),"-") -> - | P13: =IF(J13>0,J13*F13, "-") -> - | Q13: =IFERROR(IF($N$2>0, $N$2*P13, "-"), "-") -> - | S13: =IFERROR(IF(Q13+K13=0, "-", IF(Q13>0, Q13+K13, "-")), "-") -> -
A14: 27087 | B14: Melatonin 5 mg | C14: 740985270875 | D14: 120 | E14: tb | F14: 0.083856646 | G14: 24 | H14: 6.585 | I14: =IFERROR(VLOOKUP("21ST-"&A14,[1]Лист1!$B$16:$P$170,15,FALSE),"С") -> А | K14: =SUM(H14*J14) -> 0 | N14: =IFERROR(IF($N$2*F14=0, "-", $N$2*F14), "-") -> - | O14: =IFERROR(IF(N14>0,H14+N14,"-"),"-") -> - | P14: =IF(J14>0,J14*F14, "-") -> - | Q14: =IFERROR(IF($N$2>0, $N$2*P14, "-"), "-") -> - | S14: =IFERROR(IF(Q14+K14=0, "-", IF(Q14>0, Q14+K14, "-")), "-") -> -
... A132: 27474 | B132: Niacin 500 mg PR | C132: 740985274743 | D132: 100 | E132: tb | F132: 0.12485 | G132: 24 | H132: 5.745 | I132: =IFERROR(VLOOKUP("21ST-"&A132,[1]Лист1!$B$16:$P$170,15,FALSE),"С") -> С | K132: =SUM(H132*J132) -> 0 | N132: =IFERROR(IF($N$2*F132=0, "-", $N$2*F132), "-") -> - | O132: =IFERROR(IF(N132>0,H132+N132,"-"),"-") -> - | P132: =IF(J132>0,J132*F132, "-") -> - | Q132: =IFERROR(IF($N$2>0, $N$2*P132, "-"), "-") -> - | S132: =IFERROR(IF(Q132+K132=0, "-", IF(Q132>0, Q132+K132, "-")), "-") -> -
A133: 27175 | B133: PreNatal + DHA | C133: 740985271759 | D133: 60+60 | E133: tb+sg | F133: 0.26384901 | G133: 12 | H133: 20.64 | I133: =IFERROR(VLOOKUP("21ST-"&A133,[1]Лист1!$B$16:$P$170,15,FALSE),"С") -> С | K133: =SUM(H133*J133) -> 0 | N133: =IFERROR(IF($N$2*F133=0, "-", $N$2*F133), "-") -> - | O133: =IFERROR(IF(N133>0,H133+N133,"-"),"-") -> - | P133: =IF(J133>0,J133*F133, "-") -> - | Q133: =IFERROR(IF($N$2>0, $N$2*P133, "-"), "-") -> - | S133: =IFERROR(IF(Q133+K133=0, "-", IF(Q133>0, Q133+K133, "-")), "-") -> -
A134: 27384 | B134: PreNatal DHA | C134: 740985273845 | D134: 30 | E134: sg | F134: 0.060626897 | G134: 12 | H134: 9.075 | I134: =IFERROR(VLOOKUP("21ST-"&A134,[1]Лист1!$B$16:$P$170,15,FALSE),"С") -> С | K134: =SUM(H134*J134) -> 0 | N134: =IFERROR(IF($N$2*F134=0, "-", $N$2*F134), "-") -> - | O134: =IFERROR(IF(N134>0,H134+N134,"-"),"-") -> - | P134: =IF(J134>0,J134*F134, "-") -> - | Q134: =IFERROR(IF($N$2>0, $N$2*P134, "-"), "-") -> - | S134: =IFERROR(IF(Q134+K134=0, "-", IF(Q134>0, Q134+K134, "-")), "-") -> -
A135: 28011 | B135: Prostate Health | C135: 740985280119 | D135: 60 | E135: sg | F135: 0.111185 | G135: 12 | H135: 16.485 | I135: =IFERROR(VLOOKUP("21ST-"&A135,[1]Лист1!$B$16:$P$170,15,FALSE),"С") -> С | K135: =SUM(H135*J135) -> 0 | N135: =IFERROR(IF($N$2*F135=0, "-", $N$2*F135), "-") -> - | O135: =IFERROR(IF(N135>0,H135+N135,"-"),"-") -> - | P135: =IF(J135>0,J135*F135, "-") -> - | Q135: =IFERROR(IF($N$2>0, $N$2*P135, "-"), "-") -> - | S135: =IFERROR(IF(Q135+K135=0, "-", IF(Q135>0, Q135+K135, "-")), "-") -> -
A136: 27024 | B136: Psyllium | C136: 740985270240 | D136: 160 | E136: cp | F136: 0.1700296 | G136: 12 | H136: 6.585 | I136: =IFERROR(VLOOKUP("21ST-"&A136,[1]Лист1!$B$16:$P$170,15,FALSE),"С") -> С | K136: =SUM(H136*J136) -> 0 | N136: =IFERROR(IF($N$2*F136=0, "-", $N$2*F136), "-") -> - | O136: =IFERROR(IF(N136>0,H136+N136,"-"),"-") -> - | P136: =IF(J136>0,J136*F136, "-") -> - | Q136: =IFERROR(IF($N$2>0, $N$2*P136, "-"), "-") -> - | S136: =IFERROR(IF(Q136+K136=0, "-", IF(Q136>0, Q136+K136, "-")), "-") -> -
A137: 22380 | B137: Sentry | C137: 740985223802 | D137: 130 | E137: tb | F137: 0.2664065 | G137: 12 | H137: 5.745 | I137: =IFERROR(VLOOKUP("21ST-"&A137,[1]Лист1!$B$16:$P$170,15,FALSE),"С") -> С | K137: =SUM(H137*J137) -> 0 | N137: =IFERROR(IF($N$2*F137=0, "-", $N$2*F137), "-") -> - | O137: =IFERROR(IF(N137>0,H137+N137,"-"),"-") -> - | P137: =IF(J137>0,J137*F137, "-") -> - | Q137: =IFERROR(IF($N$2>0, $N$2*P137, "-"), "-") -> - | S137: =IFERROR(IF(Q137+K137=0, "-", IF(Q137>0, Q137+K137, "-")), "-") -> -
A138: 22702 | B138: Sentry | C138: 740985227022 | D138: 300 | E138: tb | F138: 0.58686079 | G138: 12 | H138: 11.925 | I138: =IFERROR(VLOOKUP("21ST-"&A138,[1]Лист1!$B$16:$P$170,15,FALSE),"С") -> С | K138: =SUM(H138*J138) -> 0 | N138: =IFERROR(IF($N$2*F138=0, "-", $N$2*F138), "-") -> - | O138: =IFERROR(IF(N138>0,H138+N138,"-"),"-") -> - | P138: =IF(J138>0,J138*F138, "-") -> - | Q138: =IFERROR(IF($N$2>0, $N$2*P138, "-"), "-") -> - | S138: =IFERROR(IF(Q138+K138=0, "-", IF(Q138>0, Q138+K138, "-")), "-") -> -
A139: 22703 | B139: Sentry Senior | C139: 740985227039 | D139: 265 | E139: tb | F139: 0.50879492 | G139: 12 | H139: 11.115 | I139: =IFERROR(VLOOKUP("21ST-"&A139,[1]Лист1!$B$16:$P$170,15,FALSE),"С") -> С | K139: =SUM(H139*J139) -> 0 | N139: =IFERROR(IF($N$2*F139=0, "-", $N$2*F139), "-") -> - | O139: =IFERROR(IF(N139>0,H139+N139,"-"),"-") -> - | P139: =IF(J139>0,J139*F139, "-") -> - | Q139: =IFERROR(IF($N$2>0, $N$2*P139, "-"), "-") -> - | S139: =IFERROR(IF(Q139+K139=0, "-", IF(Q139>0, Q139+K139, "-")), "-") -> -
A140: 22331 | B140: Stress B + Zinc | C140: 740985223314 | D140: 66 | E140: tb | F140: 0.12604389 | G140: 24 | H140: 4.965 | I140: =IFERROR(VLOOKUP("21ST-"&A140,[1]Лист1!$B$16:$P$170,15,FALSE),"С") -> С | K140: =SUM(H140*J140) -> 0 | N140: =IFERROR(IF($N$2*F140=0, "-", $N$2*F140), "-") -> - | O140: =IFERROR(IF(N140>0,H140+N140,"-"),"-") -> - | P140: =IF(J140>0,J140*F140, "-") -> - | Q140: =IFERROR(IF($N$2>0, $N$2*P140, "-"), "-") -> - | S140: =IFERROR(IF(Q140+K140=0, "-", IF(Q140>0, Q140+K140, "-")), "-") -> -
A141: 22874 | B141: Triple Omega Complex Enteric Coated | C141: 740985228746 | D141: 90 | E141: sg | F141: 0.24232221 | G141: 12 | H141: 10.5 | I141: =IFERROR(VLOOKUP("21ST-"&A141,[1]Лист1!$B$16:$P$170,15,FALSE),"С") -> С | K141: =SUM(H141*J141) -> 0 | N141: =IFERROR(IF($N$2*F141=0, "-", $N$2*F141), "-") -> - | O141: =IFERROR(IF(N141>0,H141+N141,"-"),"-") -> - | P141: =IF(J141>0,J141*F141, "-") -> - | Q141: =IFERROR(IF($N$2>0, $N$2*P141, "-"), "-") -> - | S141: =IFERROR(IF(Q141+K141=0, "-", IF(Q141>0, Q141+K141, "-")), "-") -> -
A142: 27844 | B142: Turmeric Complex | C142: 740985278444 | D142: 60 | E142: vc | F142: 0.08896406 | G142: 24 | H142: 6.585 | I142: =IFERROR(VLOOKUP("21ST-"&A142,[1]Лист1!$B$16:$P$170,15,FALSE),"С") -> С | K142: =SUM(H142*J142) -> 0 | N142: =IFERROR(IF($N$2*F142=0, "-", $N$2*F142), "-") -> - | O142: =IFERROR(IF(N142>0,H142+N142,"-"),"-") -> - | P142: =IF(J142>0,J142*F142, "-") -> - | Q142: =IFERROR(IF($N$2>0, $N$2*P142, "-"), "-") -> - | S142: =IFERROR(IF(Q142+K142=0, "-", IF(Q142>0, Q142+K142, "-")), "-") -> -
A143: 28091 | B143: Zoo Friends Probiotic | C143: 740985280911 | D143: 30 | E143: chw | F143: 0.057221954 | G143: 12 | H143: 9.9 | I143: =IFERROR(VLOOKUP("21ST-"&A143,[1]Лист1!$B$16:$P$170,15,FALSE),"С") -> С | K143: =SUM(H143*J143) -> 0 | N143: =IFERROR(IF($N$2*F143=0, "-", $N$2*F143), "-") -> - | O143: =IFERROR(IF(N143>0,H143+N143,"-"),"-") -> - | P143: =IF(J143>0,J143*F143, "-") -> - | Q143: =IFERROR(IF($N$2>0, $N$2*P143, "-"), "-") -> - | S143: =IFERROR(IF(Q143+K143=0, "-", IF(Q143>0, Q143+K143, "-")), "-") -> -
A144: 28092 | B144: Zoo Friends Sleep | C144: 740985280928 | D144: 60 | E144: chw | F144: 0.05675 | G144: 12 | H144: 4.965 | I144: =IFERROR(VLOOKUP("21ST-"&A144,[1]Лист1!$B$16:$P$170,15,FALSE),"С") -> С | K144: =SUM(H144*J144) -> 0 | N144: =IFERROR(IF($N$2*F144=0, "-", $N$2*F144), "-") -> - | O144: =IFERROR(IF(N144>0,H144+N144,"-"),"-") -> - | P144: =IF(J144>0,J144*F144, "-") -> - | Q144: =IFERROR(IF($N$2>0, $N$2*P144, "-"), "-") -> - | S144: =IFERROR(IF(Q144+K144=0, "-", IF(Q144>0, Q144+K144, "-")), "-") -> -
A145: 28056 | B145: Acidophilus Probiotic Blend | C145: 740985280560 | D145: 300 | E145: cp | F145: 0.30593615 | G145: 12 | H145: 18.9 | I145: =IFERROR(VLOOKUP("21ST-"&A145,[1]Лист1!$B$16:$P$170,15,FALSE),"С") -> С | K145: =SUM(H145*J145) -> 0 | N145: =IFERROR(IF($N$2*F145=0, "-", $N$2*F145), "-") -> - | O145: =IFERROR(IF(N145>0,H145+N145,"-"),"-") -> - | P145: =IF(J145>0,J145*F145, "-") -> - | Q145: =IFERROR(IF($N$2>0, $N$2*P145, "-"), "-") -> - | S145: =IFERROR(IF(Q145+K145=0, "-", IF(Q145>0, Q145+K145, "-")), "-") -> -
... A228: 27990 | B228: Turmeric w/ Black Pepper Extract | C228: 740985279908 | D228: 60 | E228: vc | F228: 0.094752462 | G228: 24 | H228: 8.25 | I228: =IFERROR(VLOOKUP("21ST-"&A228,[1]Лист1!$B$16:$P$170,15,FALSE),"С") -> С | K228: =SUM(H228*J228) -> 0 | N228: =IFERROR(IF($N$2*F228=0, "-", $N$2*F228), "-") -> - | O228: =IFERROR(IF(N228>0,H228+N228,"-"),"-") -> - | P228: =IF(J228>0,J228*F228, "-") -> - | Q228: =IFERROR(IF($N$2>0, $N$2*P228, "-"), "-") -> - | S228: =IFERROR(IF(Q228+K228=0, "-", IF(Q228>0, Q228+K228, "-")), "-") -> -
A229: 28086 | B229: VitaJoy B-12 3000 mcg | C229: 740985280867 | D229: 90 | E229: gmy | F229: 0.33099108 | G229: 12 | H229: 10.905 | I229: С | K229: =SUM(H229*J229) -> 0 | N229: =IFERROR(IF($N$2*F229=0, "-", $N$2*F229), "-") -> - | O229: =IFERROR(IF(N229>0,H229+N229,"-"),"-") -> - | P229: =IF(J229>0,J229*F229, "-") -> - | Q229: =IFERROR(IF($N$2>0, $N$2*P229, "-"), "-") -> - | S229: =IFERROR(IF(Q229+K229=0, "-", IF(Q229>0, Q229+K229, "-")), "-") -> -
A230: 27729 | B230: VitaJoy Biotin | C230: 740985277294 | D230: 120 | E230: gmy | F230: 0.43704332 | G230: 12 | H230: 6 | I230: С | K230: =SUM(H230*J230) -> 0 | N230: =IFERROR(IF($N$2*F230=0, "-", $N$2*F230), "-") -> - | O230: =IFERROR(IF(N230>0,H230+N230,"-"),"-") -> - | P230: =IF(J230>0,J230*F230, "-") -> - | Q230: =IFERROR(IF($N$2>0, $N$2*P230, "-"), "-") -> - | S230: =IFERROR(IF(Q230+K230=0, "-", IF(Q230>0, Q230+K230, "-")), "-") -> -
A231: 27791 | B231: VitaJoy Daily C | C231: 740985277911 | D231: 60 | E231: gmy | F231: 0.25946609 | G231: 12 | H231: 7.92 | I231: С | K231: =SUM(H231*J231) -> 0 | N231: =IFERROR(IF($N$2*F231=0, "-", $N$2*F231), "-") -> - | O231: =IFERROR(IF(N231>0,H231+N231,"-"),"-") -> - | P231: =IF(J231>0,J231*F231, "-") -> - | Q231: =IFERROR(IF($N$2>0, $N$2*P231, "-"), "-") -> - | S231: =IFERROR(IF(Q231+K231=0, "-", IF(Q231>0, Q231+K231, "-")), "-") -> -
A232: 27622 | B232: VitaJoy Daily D | C232: 740985276228 | D232: 120 | E232: gmy | F232: 0.43704332 | G232: 12 | H232: 9.9 | I232: С | K232: =SUM(H232*J232) -> 0 | N232: =IFERROR(IF($N$2*F232=0, "-", $N$2*F232), "-") -> - | O232: =IFERROR(IF(N232>0,H232+N232,"-"),"-") -> - | P232: =IF(J232>0,J232*F232, "-") -> - | Q232: =IFERROR(IF($N$2>0, $N$2*P232, "-"), "-") -> - | S232: =IFERROR(IF(Q232+K232=0, "-", IF(Q232>0, Q232+K232, "-")), "-") -> -
A233: 28017 | B233: VitaJoy Elderberry | C233: 740985280171 | D233: 60 | E233: gmy | F233: 0.26627598 | G233: 12 | H233: 9.9 | I233: С | K233: =SUM(H233*J233) -> 0 | N233: =IFERROR(IF($N$2*F233=0, "-", $N$2*F233), "-") -> - | O233: =IFERROR(IF(N233>0,H233+N233,"-"),"-") -> - | P233: =IF(J233>0,J233*F233, "-") -> - | Q233: =IFERROR(IF($N$2>0, $N$2*P233, "-"), "-") -> - | S233: =IFERROR(IF(Q233+K233=0, "-", IF(Q233>0, Q233+K233, "-")), "-") -> -
A234: 22276 | B234: VitaJoy Fiber | C234: 740985222768 | D234: 90 | E234: gmy | F234: 0.47449769 | G234: 12 | H234: 18 | I234: С | K234: =SUM(H234*J234) -> 0 | N234: =IFERROR(IF($N$2*F234=0, "-", $N$2*F234), "-") -> - | O234: =IFERROR(IF(N234>0,H234+N234,"-"),"-") -> - | P234: =IF(J234>0,J234*F234, "-") -> - | Q234: =IFERROR(IF($N$2>0, $N$2*P234, "-"), "-") -> - | S234: =IFERROR(IF(Q234+K234=0, "-", IF(Q234>0, Q234+K234, "-")), "-") -> -
A235: 27617 | B235: VitaJoy Multi | C235: 740985276174 | D235: 75 | E235: gmy | F235: 0.28840811 | G235: 12 | H235: 6.915 | I235: С | K235: =SUM(H235*J235) -> 0 | N235: =IFERROR(IF($N$2*F235=0, "-", $N$2*F235), "-") -> - | O235: =IFERROR(IF(N235>0,H235+N235,"-"),"-") -> - | P235: =IF(J235>0,J235*F235, "-") -> - | Q235: =IFERROR(IF($N$2>0, $N$2*P235, "-"), "-") -> - | S235: =IFERROR(IF(Q235+K235=0, "-", IF(Q235>0, Q235+K235, "-")), "-") -> -
A236: 27618 | B236: VitaJoy Multi | C236: 740985276181 | D236: 120 | E236: gmy | F236: 0.43704332 | G236: 12 | H236: 9.9 | I236: С | K236: =SUM(H236*J236) -> 0 | N236: =IFERROR(IF($N$2*F236=0, "-", $N$2*F236), "-") -> - | O236: =IFERROR(IF(N236>0,H236+N236,"-"),"-") -> - | P236: =IF(J236>0,J236*F236, "-") -> - | Q236: =IFERROR(IF($N$2>0, $N$2*P236, "-"), "-") -> - | S236: =IFERROR(IF(Q236+K236=0, "-", IF(Q236>0, Q236+K236, "-")), "-") -> -
A237: 22452 | B237: Wellify Men's 50+ | C237: 740985224526 | D237: 65 | E237: tb | F237: 0.15866844 | G237: 12 | H237: 8.25 | I237: С | K237: =SUM(H237*J237) -> 0 | N237: =IFERROR(IF($N$2*F237=0, "-", $N$2*F237), "-") -> - | O237: =IFERROR(IF(N237>0,H237+N237,"-"),"-") -> - | P237: =IF(J237>0,J237*F237, "-") -> - | Q237: =IFERROR(IF($N$2>0, $N$2*P237, "-"), "-") -> - | S237: =IFERROR(IF(Q237+K237=0, "-", IF(Q237>0, Q237+K237, "-")), "-") -> -
A238: 22439 | B238: Wellify Men's Energy | C238: 740985224397 | D238: 65 | E238: tb | F238: 0.14981559 | G238: 12 | H238: 8.25 | I238: С | K238: =SUM(H238*J238) -> 0 | N238: =IFERROR(IF($N$2*F238=0, "-", $N$2*F238), "-") -> - | O238: =IFERROR(IF(N238>0,H238+N238,"-"),"-") -> - | P238: =IF(J238>0,J238*F238, "-") -> - | Q238: =IFERROR(IF($N$2>0, $N$2*P238, "-"), "-") -> - | S238: =IFERROR(IF(Q238+K238=0, "-", IF(Q238>0, Q238+K238, "-")), "-") -> -
A239: 22460 | B239: Wellify Women's 50+ | C239: 740985224601 | D239: 65 | E239: tb | F239: 0.19998174 | G239: 12 | H239: 8.25 | I239: С | K239: =SUM(H239*J239) -> 0 | N239: =IFERROR(IF($N$2*F239=0, "-", $N$2*F239), "-") -> - | O239: =IFERROR(IF(N239>0,H239+N239,"-"),"-") -> - | P239: =IF(J239>0,J239*F239, "-") -> - | Q239: =IFERROR(IF($N$2>0, $N$2*P239, "-"), "-") -> - | S239: =IFERROR(IF(Q239+K239=0, "-", IF(Q239>0, Q239+K239, "-")), "-") -> -
...
